Workbook

Sheet Cómo usar
A1: Cronograma de la tesis · cómo usarlo
A2: Sprints semanales (Scrum): lunes a sábado tareas; domingo en la noche, revisión y planificación
A4: Qué es | B4: Una hoja por sprint (semana de trabajo). Cada fila es una tarea con su día, responsable, lugar, resultado y cómo saber que está terminada.
A5: Cada día | B5: Marca el Estado (Pendiente, En curso, Hecho, Movido, Cancelado) y la Fecha real cuando la termines. No borres filas.
A6: Si una tarea se mueve | B6: Estado = Movido, escribe la fecha nueva en Notas y copia la fila al día nuevo. La original queda como registro.
A7: Colores | B7: Verde = hecho · Amarillo = movido · Rojo = atrasado (pasó el día y no está hecho) · Gris tachado = cancelado.
A8: Días de retraso | B8: Se calcula solo: fecha real − día planificado; si no hay fecha real y ya pasó el día, cuenta hasta hoy.
A9: Resumen | B9: Avance por sprint y por persona, horas planificadas y tareas atrasadas, con gráfico. Se calcula solo.
A10: Carga | B10: Horas y tareas por persona y día. Rojo si pasa de 2 h entre semana, 4 h el fin de semana o 4 tareas.
A11: Domingo en la noche | B11: Revisión del sprint (qué hicimos, qué no, qué aprendimos) + 20 minutos de «explícame lo tuyo» + planificación del sprint siguiente. Lo que se decida se anota en 11_Planificacion/Bitacora_Semanal.md.
A12: Entregable (issue) | B12: Cada tarea pertenece a un entregable que tiene su ficha en GitHub (issue). Ejemplo: «S1-07 (#7)» = entregable 7 del sprint 1, ficha #7 en github.com/l333x/Tesis_Torvesa/issues/7.
A13: Códigos | B13: M1–M6 = metas de validación · A1–A47 = afirmaciones que necesitan fuente · LOPDP = ley de datos personales · BPMN = forma estándar de dibujar procesos. Todo está en Glosario.pdf (raíz del repo).
A14: Escenario A | B14: Si la tutora confirma el 15-dic como fecha obligatoria, se comprime diciembre y se eliminan primero las tareas marcadas con ✂.
A15: Versión para la IA | B15: 11_Planificacion/CRONOGRAMA.md se regenera desde este Excel (comando: python 99_Scripts/gestion/generar_cronograma.py --md).

Sheet Resumen
A1: Resumen del avance
A2: Se calcula solo desde las hojas de cada sprint. No escribas aquí.
A4: Sprint | B4: Fechas y objetivo | C4: Tareas | D4: Hechas | E4: % avance | F4: % Víctor | G4: % Diego | H4: Horas Víctor | I4: Horas Diego | J4: Atrasadas
A5: S1 | B5: Sprint 1 · 12–18 oct · Recopilar información | C5: =COUNTA('S1'!D6:D32)-COUNTIF('S1'!K6:K32,"Cancelado") | D5: =COUNTIF('S1'!K6:K32,"Hecho") | E5: =IFERROR(D5/C5,0) | F5: =IFERROR((COUNTIFS('S1'!E6:E32,"Víctor",'S1'!K6:K32,"Hecho")+COUNTIFS('S1'!E6:E32,"Ambos",'S1'!K6:K32,"Hecho"))/(COUNTIF('S1'!E6:E32,"Víctor")+COUNTIF('S1'!E6:E32,"Ambos")),0) | G5: =IFERROR((COUNTIFS('S1'!E6:E32,"Diego",'S1'!K6:K32,"Hecho")+COUNTIFS('S1'!E6:E32,"Ambos",'S1'!K6:K32,"Hecho"))/(COUNTIF('S1'!E6:E32,"Diego")+COUNTIF('S1'!E6:E32,"Ambos")),0) | H5: =SUMIF('S1'!E6:E32,"Víctor",'S1'!I6:I32)+SUMIF('S1'!E6:E32,"Ambos",'S1'!I6:I32) | I5: =SUMIF('S1'!E6:E32,"Diego",'S1'!I6:I32)+SUMIF('S1'!E6:E32,"Ambos",'S1'!I6:I32) | J5: =COUNTIF('S1'!L6:L32,">0")
A6: S2 | B6: Sprint 2 · 19–25 oct · Redactar capítulos | C6: =COUNTA('S2'!D6:D23)-COUNTIF('S2'!K6:K23,"Cancelado") | D6: =COUNTIF('S2'!K6:K23,"Hecho") | E6: =IFERROR(D6/C6,0) | F6: =IFERROR((COUNTIFS('S2'!E6:E23,"Víctor",'S2'!K6:K23,"Hecho")+COUNTIFS('S2'!E6:E23,"Ambos",'S2'!K6:K23,"Hecho"))/(COUNTIF('S2'!E6:E23,"Víctor")+COUNTIF('S2'!E6:E23,"Ambos")),0) | G6: =IFERROR((COUNTIFS('S2'!E6:E23,"Diego",'S2'!K6:K23,"Hecho")+COUNTIFS('S2'!E6:E23,"Ambos",'S2'!K6:K23,"Hecho"))/(COUNTIF('S2'!E6:E23,"Diego")+COUNTIF('S2'!E6:E23,"Ambos")),0) | H6: =SUMIF('S2'!E6:E23,"Víctor",'S2'!I6:I23)+SUMIF('S2'!E6:E23,"Ambos",'S2'!I6:I23) | I6: =SUMIF('S2'!E6:E23,"Diego",'S2'!I6:I23)+SUMIF('S2'!E6:E23,"Ambos",'S2'!I6:I23) | J6: =COUNTIF('S2'!L6:L23,">0")
A7: S3 | B7: Sprint 3 · 26 oct–1 nov · Revisión 1 con la tutora | C7: =COUNTA('S3'!D6:D24)-COUNTIF('S3'!K6:K24,"Cancelado") | D7: =COUNTIF('S3'!K6:K24,"Hecho") | E7: =IFERROR(D7/C7,0) | F7: =IFERROR((COUNTIFS('S3'!E6:E24,"Víctor",'S3'!K6:K24,"Hecho")+COUNTIFS('S3'!E6:E24,"Ambos",'S3'!K6:K24,"Hecho"))/(COUNTIF('S3'!E6:E24,"Víctor")+COUNTIF('S3'!E6:E24,"Ambos")),0) | G7: =IFERROR((COUNTIFS('S3'!E6:E24,"Diego",'S3'!K6:K24,"Hecho")+COUNTIFS('S3'!E6:E24,"Ambos",'S3'!K6:K24,"Hecho"))/(COUNTIF('S3'!E6:E24,"Diego")+COUNTIF('S3'!E6:E24,"Ambos")),0) | H7: =SUMIF('S3'!E6:E24,"Víctor",'S3'!I6:I24)+SUMIF('S3'!E6:E24,"Ambos",'S3'!I6:I24) | I7: =SUMIF('S3'!E6:E24,"Diego",'S3'!I6:I24)+SUMIF('S3'!E6:E24,"Ambos",'S3'!I6:I24) | J7: =COUNTIF('S3'!L6:L24,">0")
A8: S4 | B8: Sprint 4 · 2–8 nov · Diseñar el sistema | C8: =COUNTA('S4'!D6:D22)-COUNTIF('S4'!K6:K22,"Cancelado") | D8: =COUNTIF('S4'!K6:K22,"Hecho") | E8: =IFERROR(D8/C8,0) | F8: =IFERROR((COUNTIFS('S4'!E6:E22,"Víctor",'S4'!K6:K22,"Hecho")+COUNTIFS('S4'!E6:E22,"Ambos",'S4'!K6:K22,"Hecho"))/(COUNTIF('S4'!E6:E22,"Víctor")+COUNTIF('S4'!E6:E22,"Ambos")),0) | G8: =IFERROR((COUNTIFS('S4'!E6:E22,"Diego",'S4'!K6:K22,"Hecho")+COUNTIFS('S4'!E6:E22,"Ambos",'S4'!K6:K22,"Hecho"))/(COUNTIF('S4'!E6:E22,"Diego")+COUNTIF('S4'!E6:E22,"Ambos")),0) | H8: =SUMIF('S4'!E6:E22,"Víctor",'S4'!I6:I22)+SUMIF('S4'!E6:E22,"Ambos",'S4'!I6:I22) | I8: =SUMIF('S4'!E6:E22,"Diego",'S4'!I6:I22)+SUMIF('S4'!E6:E22,"Ambos",'S4'!I6:I22) | J8: =COUNTIF('S4'!L6:L22,">0")
A9: S5 | B9: Sprint 5 · 9–15 nov · Prueba de concepto y finanzas | C9: =COUNTA('S5'!D6:D20)-COUNTIF('S5'!K6:K20,"Cancelado") | D9: =COUNTIF('S5'!K6:K20,"Hecho") | E9: =IFERROR(D9/C9,0) | F9: =IFERROR((COUNTIFS('S5'!E6:E20,"Víctor",'S5'!K6:K20,"Hecho")+COUNTIFS('S5'!E6:E20,"Ambos",'S5'!K6:K20,"Hecho"))/(COUNTIF('S5'!E6:E20,"Víctor")+COUNTIF('S5'!E6:E20,"Ambos")),0) | G9: =IFERROR((COUNTIFS('S5'!E6:E20,"Diego",'S5'!K6:K20,"Hecho")+COUNTIFS('S5'!E6:E20,"Ambos",'S5'!K6:K20,"Hecho"))/(COUNTIF('S5'!E6:E20,"Diego")+COUNTIF('S5'!E6:E20,"Ambos")),0) | H9: =SUMIF('S5'!E6:E20,"Víctor",'S5'!I6:I20)+SUMIF('S5'!E6:E20,"Ambos",'S5'!I6:I20) | I9: =SUMIF('S5'!E6:E20,"Diego",'S5'!I6:I20)+SUMIF('S5'!E6:E20,"Ambos",'S5'!I6:I20) | J9: =COUNTIF('S5'!L6:L20,">0")
A10: S6 | B10: Sprint 6 · 16–22 nov · Revisión 2 con la tutora | C10: =COUNTA('S6'!D6:D17)-COUNTIF('S6'!K6:K17,"Cancelado") | D10: =COUNTIF('S6'!K6:K17,"Hecho") | E10: =IFERROR(D10/C10,0) | F10: =IFERROR((COUNTIFS('S6'!E6:E17,"Víctor",'S6'!K6:K17,"Hecho")+COUNTIFS('S6'!E6:E17,"Ambos",'S6'!K6:K17,"Hecho"))/(COUNTIF('S6'!E6:E17,"Víctor")+COUNTIF('S6'!E6:E17,"Ambos")),0) | G10: =IFERROR((COUNTIFS('S6'!E6:E17,"Diego",'S6'!K6:K17,"Hecho")+COUNTIFS('S6'!E6:E17,"Ambos",'S6'!K6:K17,"Hecho"))/(COUNTIF('S6'!E6:E17,"Diego")+COUNTIF('S6'!E6:E17,"Ambos")),0) | H10: =SUMIF('S6'!E6:E17,"Víctor",'S6'!I6:I17)+SUMIF('S6'!E6:E17,"Ambos",'S6'!I6:I17) | I10: =SUMIF('S6'!E6:E17,"Diego",'S6'!I6:I17)+SUMIF('S6'!E6:E17,"Ambos",'S6'!I6:I17) | J10: =COUNTIF('S6'!L6:L17,">0")
A11: S7 | B11: Sprint 7 · 23–29 nov · Arranca la validación | C11: =COUNTA('S7'!D6:D19)-COUNTIF('S7'!K6:K19,"Cancelado") | D11: =COUNTIF('S7'!K6:K19,"Hecho") | E11: =IFERROR(D11/C11,0) | F11: =IFERROR((COUNTIFS('S7'!E6:E19,"Víctor",'S7'!K6:K19,"Hecho")+COUNTIFS('S7'!E6:E19,"Ambos",'S7'!K6:K19,"Hecho"))/(COUNTIF('S7'!E6:E19,"Víctor")+COUNTIF('S7'!E6:E19,"Ambos")),0) | G11: =IFERROR((COUNTIFS('S7'!E6:E19,"Diego",'S7'!K6:K19,"Hecho")+COUNTIFS('S7'!E6:E19,"Ambos",'S7'!K6:K19,"Hecho"))/(COUNTIF('S7'!E6:E19,"Diego")+COUNTIF('S7'!E6:E19,"Ambos")),0) | H11: =SUMIF('S7'!E6:E19,"Víctor",'S7'!I6:I19)+SUMIF('S7'!E6:E19,"Ambos",'S7'!I6:I19) | I11: =SUMIF('S7'!E6:E19,"Diego",'S7'!I6:I19)+SUMIF('S7'!E6:E19,"Ambos",'S7'!I6:I19) | J11: =COUNTIF('S7'!L6:L19,">0")
A12: S8 | B12: Sprint 8 · 30 nov–6 dic · Documentar el sistema | C12: =COUNTA('S8'!D6:D23)-COUNTIF('S8'!K6:K23,"Cancelado") | D12: =COUNTIF('S8'!K6:K23,"Hecho") | E12: =IFERROR(D12/C12,0) | F12: =IFERROR((COUNTIFS('S8'!E6:E23,"Víctor",'S8'!K6:K23,"Hecho")+COUNTIFS('S8'!E6:E23,"Ambos",'S8'!K6:K23,"Hecho"))/(COUNTIF('S8'!E6:E23,"Víctor")+COUNTIF('S8'!E6:E23,"Ambos")),0) | G12: =IFERROR((COUNTIFS('S8'!E6:E23,"Diego",'S8'!K6:K23,"Hecho")+COUNTIFS('S8'!E6:E23,"Ambos",'S8'!K6:K23,"Hecho"))/(COUNTIF('S8'!E6:E23,"Diego")+COUNTIF('S8'!E6:E23,"Ambos")),0) | H12: =SUMIF('S8'!E6:E23,"Víctor",'S8'!I6:I23)+SUMIF('S8'!E6:E23,"Ambos",'S8'!I6:I23) | I12: =SUMIF('S8'!E6:E23,"Diego",'S8'!I6:I23)+SUMIF('S8'!E6:E23,"Ambos",'S8'!I6:I23) | J12: =COUNTIF('S8'!L6:L23,">0")
A13: S9 | B13: Sprint 9 · 7–13 dic · Medir el «después» y comparar | C13: =COUNTA('S9'!D6:D15)-COUNTIF('S9'!K6:K15,"Cancelado") | D13: =COUNTIF('S9'!K6:K15,"Hecho") | E13: =IFERROR(D13/C13,0) | F13: =IFERROR((COUNTIFS('S9'!E6:E15,"Víctor",'S9'!K6:K15,"Hecho")+COUNTIFS('S9'!E6:E15,"Ambos",'S9'!K6:K15,"Hecho"))/(COUNTIF('S9'!E6:E15,"Víctor")+COUNTIF('S9'!E6:E15,"Ambos")),0) | G13: =IFERROR((COUNTIFS('S9'!E6:E15,"Diego",'S9'!K6:K15,"Hecho")+COUNTIFS('S9'!E6:E15,"Ambos",'S9'!K6:K15,"Hecho"))/(COUNTIF('S9'!E6:E15,"Diego")+COUNTIF('S9'!E6:E15,"Ambos")),0) | H13: =SUMIF('S9'!E6:E15,"Víctor",'S9'!I6:I15)+SUMIF('S9'!E6:E15,"Ambos",'S9'!I6:I15) | I13: =SUMIF('S9'!E6:E15,"Diego",'S9'!I6:I15)+SUMIF('S9'!E6:E15,"Ambos",'S9'!I6:I15) | J13: =COUNTIF('S9'!L6:L15,">0")
A14: S10 | B14: Sprint 10 · 14–20 dic · Cierre e hito del 90 % | C14: =COUNTA('S10'!D6:D13)-COUNTIF('S10'!K6:K13,"Cancelado") | D14: =COUNTIF('S10'!K6:K13,"Hecho") | E14: =IFERROR(D14/C14,0) | F14: =IFERROR((COUNTIFS('S10'!E6:E13,"Víctor",'S10'!K6:K13,"Hecho")+COUNTIFS('S10'!E6:E13,"Ambos",'S10'!K6:K13,"Hecho"))/(COUNTIF('S10'!E6:E13,"Víctor")+COUNTIF('S10'!E6:E13,"Ambos")),0) | G14: =IFERROR((COUNTIFS('S10'!E6:E13,"Diego",'S10'!K6:K13,"Hecho")+COUNTIFS('S10'!E6:E13,"Ambos",'S10'!K6:K13,"Hecho"))/(COUNTIF('S10'!E6:E13,"Diego")+COUNTIF('S10'!E6:E13,"Ambos")),0) | H14: =SUMIF('S10'!E6:E13,"Víctor",'S10'!I6:I13)+SUMIF('S10'!E6:E13,"Ambos",'S10'!I6:I13) | I14: =SUMIF('S10'!E6:E13,"Diego",'S10'!I6:I13)+SUMIF('S10'!E6:E13,"Ambos",'S10'!I6:I13) | J14: =COUNTIF('S10'!L6:L13,">0")
A15: Holgura | B15: Holgura · 21 dic–3 ene · Pulir | C15: =COUNTA('Holgura'!D6:D11)-COUNTIF('Holgura'!K6:K11,"Cancelado") | D15: =COUNTIF('Holgura'!K6:K11,"Hecho") | E15: =IFERROR(D15/C15,0) | F15: =IFERROR((COUNTIFS('Holgura'!E6:E11,"Víctor",'Holgura'!K6:K11,"Hecho")+COUNTIFS('Holgura'!E6:E11,"Ambos",'Holgura'!K6:K11,"Hecho"))/(COUNTIF('Holgura'!E6:E11,"Víctor")+COUNTIF('Holgura'!E6:E11,"Ambos")),0) | G15: =IFERROR((COUNTIFS('Holgura'!E6:E11,"Diego",'Holgura'!K6:K11,"Hecho")+COUNTIFS('Holgura'!E6:E11,"Ambos",'Holgura'!K6:K11,"Hecho"))/(COUNTIF('Holgura'!E6:E11,"Diego")+COUNTIF('Holgura'!E6:E11,"Ambos")),0) | H15: =SUMIF('Holgura'!E6:E11,"Víctor",'Holgura'!I6:I11)+SUMIF('Holgura'!E6:E11,"Ambos",'Holgura'!I6:I11) | I15: =SUMIF('Holgura'!E6:E11,"Diego",'Holgura'!I6:I11)+SUMIF('Holgura'!E6:E11,"Ambos",'Holgura'!I6:I11) | J15: =COUNTIF('Holgura'!L6:L11,">0")
A16: Entrega | B16: Entrega · 4–10 ene · Revisión final y firma | C16: =COUNTA('Entrega'!D6:D9)-COUNTIF('Entrega'!K6:K9,"Cancelado") | D16: =COUNTIF('Entrega'!K6:K9,"Hecho") | E16: =IFERROR(D16/C16,0) | F16: =IFERROR((COUNTIFS('Entrega'!E6:E9,"Víctor",'Entrega'!K6:K9,"Hecho")+COUNTIFS('Entrega'!E6:E9,"Ambos",'Entrega'!K6:K9,"Hecho"))/(COUNTIF('Entrega'!E6:E9,"Víctor")+COUNTIF('Entrega'!E6:E9,"Ambos")),0) | G16: =IFERROR((COUNTIFS('Entrega'!E6:E9,"Diego",'Entrega'!K6:K9,"Hecho")+COUNTIFS('Entrega'!E6:E9,"Ambos",'Entrega'!K6:K9,"Hecho"))/(COUNTIF('Entrega'!E6:E9,"Diego")+COUNTIF('Entrega'!E6:E9,"Ambos")),0) | H16: =SUMIF('Entrega'!E6:E9,"Víctor",'Entrega'!I6:I9)+SUMIF('Entrega'!E6:E9,"Ambos",'Entrega'!I6:I9) | I16: =SUMIF('Entrega'!E6:E9,"Diego",'Entrega'!I6:I9)+SUMIF('Entrega'!E6:E9,"Ambos",'Entrega'!I6:I9) | J16: =COUNTIF('Entrega'!L6:L9,">0")
A17: Defensa | B17: Defensa · 11 ene–12 feb · Preparar y defender | C17: =COUNTA('Defensa'!D6:D10)-COUNTIF('Defensa'!K6:K10,"Cancelado") | D17: =COUNTIF('Defensa'!K6:K10,"Hecho") | E17: =IFERROR(D17/C17,0) | F17: =IFERROR((COUNTIFS('Defensa'!E6:E10,"Víctor",'Defensa'!K6:K10,"Hecho")+COUNTIFS('Defensa'!E6:E10,"Ambos",'Defensa'!K6:K10,"Hecho"))/(COUNTIF('Defensa'!E6:E10,"Víctor")+COUNTIF('Defensa'!E6:E10,"Ambos")),0) | G17: =IFERROR((COUNTIFS('Defensa'!E6:E10,"Diego",'Defensa'!K6:K10,"Hecho")+COUNTIFS('Defensa'!E6:E10,"Ambos",'Defensa'!K6:K10,"Hecho"))/(COUNTIF('Defensa'!E6:E10,"Diego")+COUNTIF('Defensa'!E6:E10,"Ambos")),0) | H17: =SUMIF('Defensa'!E6:E10,"Víctor",'Defensa'!I6:I10)+SUMIF('Defensa'!E6:E10,"Ambos",'Defensa'!I6:I10) | I17: =SUMIF('Defensa'!E6:E10,"Diego",'Defensa'!I6:I10)+SUMIF('Defensa'!E6:E10,"Ambos",'Defensa'!I6:I10) | J17: =COUNTIF('Defensa'!L6:L10,">0")
A18: TOTAL | C18: =SUM(C5:C17) | D18: =SUM(D5:D17) | E18: =IFERROR(D18/C18,0) | H18: =SUM(H5:H17) | I18: =SUM(I5:I17) | J18: =SUM(J5:J17)

Sheet S1
A1: Sprint 1 · 12–18 oct · Recopilar información
A2: Objetivo: Buscar fuentes, hablar con la tutora y con Torvesa, preparar el campo
A3: Avance del sprint: | C3: =IFERROR(COUNTIF(K6:K32,"Hecho")/(COUNTA(D6:D32)-COUNTIF(K6:K32,"Cancelado")),0) | D3: ="Víctor: "&TEXT(IFERROR((COUNTIFS(E6:E32,"Víctor",K6:K32,"Hecho")+COUNTIFS(E6:E32,"Ambos",K6:K32,"Hecho"))/(COUNTIF(E6:E32,"Víctor")+COUNTIF(E6:E32,"Ambos")),0),"0%")&" · Diego: "&TEXT(IFERROR((COUNTIFS(E6:E32,"Diego",K6:K32,"Hecho")+COUNTIFS(E6:E32,"Ambos",K6:K32,"Hecho"))/(COUNTIF(E6:E32,"Diego")+COUNTIF(E6:E32,"Ambos")),0),"0%")&" · Horas: "&TEXT(SUM(I6:I32),"0.0")
A5: ID | B5: Día planificado | C5: Día | D5: Tarea (verbo + qué + para qué) | E5: Responsable | F5: Dónde se hace | G5: Resultado esperado | H5: Cómo sé que terminé | I5: Horas estimadas | J5: Fecha real | K5: Estado | L5: Días de retraso | M5: Entregable (issue) | N5: Notas
A6: S1-T01 | B6: 46307 | C6: =B6 | D6: Conversar con la tutora sobre los 5 cambios, para tener su aprobación | E6: Víctor | F6: UPS Quito, en persona · llevar 08_Reuniones_Tutora/2026-10-12_Puntos_Tutora.pdf | G6: Respuestas de la tutora anotadas | H6: Las 5 preguntas tienen respuesta (sí / no / pendiente) | I6: 1 | J6: 46307 | K6: Hecho | L6: =IF(K6="Cancelado","",IF(J6<>"",J6-B6,IF(AND(K6<>"Hecho",TODAY()>B6),TODAY()-B6,0))) | M6: S1-07 (#7) | N6: Víctor conversó con la tutora: sin objeciones a los 5 puntos (lo dijo Víctor el 18-oct). Falta confirmar la fecha de entrega (D5)
A7: S1-T02 | B7: 46307 | C7: =B7 | D7: Escribir el acta de la conversación, para que quede por escrito lo que decidió | E7: Víctor | F7: 08_Reuniones_Tutora/ | G7: 08_Reuniones_Tutora/2026-10-12_Acta_Conversacion.md | H7: Acta con decisiones y fechas | I7: 0.5 | K7: Movido | L7: =IF(K7="Cancelado","",IF(J7<>"",J7-B7,IF(AND(K7<>"Hecho",TODAY()>B7),TODAY()-B7,0))) | M7: S1-07 (#7) | N7: Víctor decidió hacer el acta más adelante (18-oct)
A8: S1-T03 | B8: 46307 | C8: =B8 | D8: Enviar el correo a Torvesa (giro, nota de respaldo, catálogo, permisos), para trabajar con datos oficiales | E8: Víctor | F8: Correo electrónico · borrador en 11_Planificacion/2026-10-12_Correo_Torvesa_borrador.docx | G8: Correo enviado con el catálogo adjunto | H8: Copia del correo enviado | I8: 0.5 | K8: Movido | L8: =IF(K8="Cancelado","",IF(J8<>"",J8-B8,IF(AND(K8<>"Hecho",TODAY()>B8),TODAY()-B8,0))) | M8: S1-05 (#5) | N8: Diego se encarga de conseguir la información de Torvesa (decisión de Víctor, 18-oct)
A9: S1-T04 | B9: 46307 | C9: =B9 | D9: Aceptar la invitación de GitHub y clonar el repo, para trabajar en la bóveda compartida | E9: Diego | F9: PC de Diego · pasos en GUIA_DIEGO.pdf (raíz) | G9: Repo clonado + 00_Inbox/hola_diego.md | H9: El commit de prueba aparece en GitHub | I9: 1 | J9: 46314 | K9: Hecho | L9: =IF(K9="Cancelado","",IF(J9<>"",J9-B9,IF(AND(K9<>"Hecho",TODAY()>B9),TODAY()-B9,0))) | M9: S1-10 (#10) | N9: Diego acepta la invitación el 18-oct (vencía ese día) · 19-oct: repo clonado y commit de prueba (00_Inbox/hola_diego.md)
A10: S1-T05 | B10: 46307 | C10: =B10 | D10: Levantar el buscador RAG en su PC, para consultar la bóveda | E10: Diego | F10: PC de Diego · pasos en RAG_README.md (raíz) | G10: Consulta de prueba con resultados | H10: rag.py consultar devuelve fragmentos | I10: 1 | J10: 46314 | K10: Hecho | L10: =IF(K10="Cancelado","",IF(J10<>"",J10-B10,IF(AND(K10<>"Hecho",TODAY()>B10),TODAY()-B10,0))) | M10: S1-10 (#10) | N10: Movido a la semana 19–24 oct (bloques dobles de Diego en IA_DIEGO.md) · 19-oct: RAG funcionando en la PC de Diego (586 notas indexadas)
A11: S1-T06 | B11: 46308 | C11: =B11 | D11: Buscar y verificar fuentes sobre el tiempo de respuesta a clientes (Oldroyd y estudios 2023+), para respaldar el problema (A9, A10) | E11: Víctor | F11: 02_Fuentes/Problema/ · con 99_Scripts/busqueda/ | G11: ≥5 fichas, ≥2 verificadas con página | H11: Cada ficha con estado y página | I11: 1 | K11: En curso | L11: =IF(K11="Cancelado","",IF(J11<>"",J11-B11,IF(AND(K11<>"Hecho",TODAY()>B11),TODAY()-B11,0))) | M11: S1-01 (#1) | N11: A9 parcial (falta el PDF de Oldroyd); A10 hay que reformularla como decisión de diseño. Ver la matriz del 18-oct
A12: S1-T07 | B12: 46308 | C12: =B12 | D12: Buscar fuentes sobre la digitalización de la construcción, para respaldar el contexto (A5, A6) | E12: Víctor | F12: 02_Fuentes/Problema/ | G12: ≥4 fichas | H12: Cada ficha con estado | I12: 1 | J12: 46307 | K12: Hecho | L12: =IF(K12="Cancelado","",IF(J12<>"",J12-B12,IF(AND(K12<>"Hecho",TODAY()>B12),TODAY()-B12,0))) | M12: S1-01 (#1) | N12: A5 y A6 respaldadas (Manyika 2015, Cathles 2023, Samuelson 2023, McKinsey 2023). Nyqvist 2024 opcional
A13: S1-T08 | B13: 46308 | C13: =B13 | D13: Investigar cómo consolidar bóvedas de conocimiento, para diseñar la bóveda del sistema | E13: Diego | F13: 02_Fuentes/Tecnologia_IA/ · con 99_Scripts/busqueda/ | G13: ≥5 fichas | H13: Cada ficha dice qué respalda | I13: 1.5 | J13: 46316 | K13: Hecho | L13: =IF(K13="Cancelado","",IF(J13<>"",J13-B13,IF(AND(K13<>"Hecho",TODAY()>B13),TODAY()-B13,0))) | M13: S1-13 (#54) | N13: Movido a la semana 19–24 oct (bloques dobles de Diego en IA_DIEGO.md) · 21-oct: 7 fichas verificadas de gestión del conocimiento (D01)
A14: S1-T09 | B14: 46308 | C14: =B14 | D14: Leer el Documento madre y el Glosario, para entender el proyecto completo | E14: Diego | F14: 00_DOCUMENTO_MADRE.pdf y Glosario.pdf (raíz) | G14: Dudas anotadas en el issue #10 | H14: Dudas enviadas a Víctor | I14: 0.5 | J14: 46314 | K14: Hecho | L14: =IF(K14="Cancelado","",IF(J14<>"",J14-B14,IF(AND(K14<>"Hecho",TODAY()>B14),TODAY()-B14,0))) | M14: S1-10 (#10) | N14: Movido a la semana 19–24 oct (bloques dobles de Diego en IA_DIEGO.md) · 19-oct: leído; 5 dudas en 00_Inbox/2026-10-19_reporte_Diego.md
A15: S1-T10 | B15: 46309 | C15: =B15 | D15: Revisar la respuesta de Torvesa y ajustar el campo del jueves y viernes, para saber qué se puede aplicar | E15: Víctor | F15: Correo · 11_Planificacion/Cronograma_Tesis.xlsx | G15: Campo confirmado o reprogramado | H15: Notas de esta fila actualizadas | I15: 0.25 | K15: Movido | L15: =IF(K15="Cancelado","",IF(J15<>"",J15-B15,IF(AND(K15<>"Hecho",TODAY()>B15),TODAY()-B15,0))) | M15: S1-05 (#5) | N15: Movido: se aplica cuando Torvesa autorice (Diego consigue la información y los permisos)
A16: S1-T11 | B16: 46309 | C16: =B16 | D16: Corregir los instrumentos a la versión 0.2, para aplicarlos en Torvesa | E16: Víctor | F16: 04_Instrumentos/ | G16: 04_Instrumentos/2026-10-14_*_v0.2 (.md + Word) | H16: Aprobados e impresos | I16: 0.75 | J16: 46313 | K16: Hecho | L16: =IF(K16="Cancelado","",IF(J16<>"",J16-B16,IF(AND(K16<>"Hecho",TODAY()>B16),TODAY()-B16,0))) | M16: S1-04 (#4) | N16: C1 v0.2 (artículos de la LOPDP) e I1 v0.2 (SUS validada en español) en 04_Instrumentos/2026-10-18_*. I2, I3, P1 y P2 siguen en v0.1
A17: S1-T12 | B17: 46309 | C17: =B17 | D17: Hacer el corte de fuentes: armar la matriz afirmación–fuente–estado, para decidir qué entra al capítulo 1 | E17: Víctor | F17: 03_Matriz_Objetivos/ | G17: 03_Matriz_Objetivos/2026-10-14_Matriz_Afirmaciones_v0.1.xlsx | H17: Las 47 afirmaciones tienen estado | I17: 1 | J17: 46313 | K17: Hecho | L17: =IF(K17="Cancelado","",IF(J17<>"",J17-B17,IF(AND(K17<>"Hecho",TODAY()>B17),TODAY()-B17,0))) | M17: S1-03 (#3) | N17: 03_Matriz_Objetivos/2026-10-18_Matriz_Afirmaciones_v0.1.xlsx: 9 respaldadas, 7 parciales, 1 reformular, 5 de campo, 1 no se usa, 19 sin fuente
A18: S1-T13 | B18: 46309 | C18: =B18 | D18: Investigar arquitecturas RAG para negocio, para proponer cómo el asistente consultará la bóveda | E18: Diego | F18: 02_Fuentes/Tecnologia_IA/ | G18: ≥5 fichas | H18: Cada ficha dice qué respalda | I18: 1.5 | J18: 46316 | K18: Hecho | L18: =IF(K18="Cancelado","",IF(J18<>"",J18-B18,IF(AND(K18<>"Hecho",TODAY()>B18),TODAY()-B18,0))) | M18: S1-13 (#54) | N18: Movido a la semana 19–24 oct (bloques dobles de Diego en IA_DIEGO.md) · 21-oct: 6 fichas verificadas de RAG (D02); A37 cubierta
A19: S1-T14 | B19: 46309 | C19: =B19 | D19: Escribir un resumen de 1 página para Víctor sobre bóvedas y RAG, para compartir lo aprendido | E19: Diego | F19: 02_Fuentes/Tecnologia_IA/ | G19: 02_Fuentes/Tecnologia_IA/2026-10-14_Resumen_Bovedas_RAG.md | H19: Víctor lo leyó | I19: 0.5 | J19: 46320 | K19: Hecho | L19: =IF(K19="Cancelado","",IF(J19<>"",J19-B19,IF(AND(K19<>"Hecho",TODAY()>B19),TODAY()-B19,0))) | M19: S1-13 (#54) | N19: Movido a la semana 19–24 oct (bloques dobles de Diego en IA_DIEGO.md) · 25-oct: 02_Fuentes/Tecnologia_IA/2026-10-25_Resumen_Bovedas_RAG.md
A20: S1-T15 | B20: 46310 | C20: =B20 | D20: Aplicar la encuesta a colaboradores y 2 entrevistas en Torvesa (si autorizó), para la línea base real | E20: Víctor | F20: Torvesa (oficina, Quito) · registro en 05_Datos_Campo/LineaBase_2026-10/ | G20: Hojas firmadas + 05_Datos_Campo/LineaBase_2026-10/registro_aplicacion.csv | H20: Cada aplicación está en el registro | I20: 2 | K20: Movido | L20: =IF(K20="Cancelado","",IF(J20<>"",J20-B20,IF(AND(K20<>"Hecho",TODAY()>B20),TODAY()-B20,0))) | M20: S1-08 (#8) | N20: Movido: se aplica cuando Torvesa autorice (Diego consigue la información y los permisos)
A21: S1-T16 | B21: 46310 | C21: =B21 | D21: Cronometrar las cotizaciones del día en Torvesa (si autorizó), para medir el tiempo real (meta M2) | E21: Diego | F21: Torvesa (oficina, Quito) | G21: 05_Datos_Campo/LineaBase_2026-10/P2A_cronometraje.csv | H21: Todas las cotizaciones observadas registradas | I21: 2 | K21: Movido | L21: =IF(K21="Cancelado","",IF(J21<>"",J21-B21,IF(AND(K21<>"Hecho",TODAY()>B21),TODAY()-B21,0))) | M21: S1-09 (#9) | N21: Movido: se aplica cuando Torvesa autorice (Diego consigue la información y los permisos) · 27-oct: bloqueada, Torvesa aún no autoriza el campo; copia en S4-T16 (reprogramada 27-oct)
A22: S1-T17 | B22: 46311 | C22: =B22 | D22: Llamar a los clientes para la encuesta corta (si autorizó), para conocer su experiencia | E22: Víctor | F22: Teléfono · lista solo en 05_Datos_Campo/_crudo/ (privada) | G22: Respuestas codificadas CLI-xx | H22: Cada llamada con consentimiento verbal registrado | I22: 2 | K22: Movido | L22: =IF(K22="Cancelado","",IF(J22<>"",J22-B22,IF(AND(K22<>"Hecho",TODAY()>B22),TODAY()-B22,0))) | M22: S1-08 (#8) | N22: Movido: se aplica cuando Torvesa autorice (Diego consigue la información y los permisos)
A23: S1-T18 | B23: 46311 | C23: =B23 | D23: Revisar solicitudes y cotizaciones de los últimos 3 meses (solo fechas y horas), para medir el tiempo de respuesta (meta M1) | E23: Diego | F23: Torvesa (oficina, Quito) | G23: 05_Datos_Campo/LineaBase_2026-10/P2B_muestra_documental.csv | H23: ≥20 solicitudes o todas las disponibles | I23: 2 | K23: Movido | L23: =IF(K23="Cancelado","",IF(J23<>"",J23-B23,IF(AND(K23<>"Hecho",TODAY()>B23),TODAY()-B23,0))) | M23: S1-09 (#9) | N23: Movido: se aplica cuando Torvesa autorice (Diego consigue la información y los permisos) · 27-oct: bloqueada, Torvesa aún no autoriza el campo; copia en S4-T16 (reprogramada 27-oct)
A24: S1-T19 | B24: 46312 | C24: =B24 | D24: Buscar el texto oficial de la ley de datos (LOPDP) y agregar sus artículos al consentimiento, para cumplir la ley | E24: Víctor | F24: 02_Fuentes/Normativa/ y 04_Instrumentos/ | G24: Ficha LOPDP + consentimiento v0.2 con artículos | H24: Artículos citados desde el Registro Oficial | I24: 1.5 | J24: 46313 | K24: Hecho | L24: =IF(K24="Cancelado","",IF(J24<>"",J24-B24,IF(AND(K24<>"Hecho",TODAY()>B24),TODAY()-B24,0))) | M24: S1-02 (#2) | N24: LOPDP verificada en el Registro Oficial (RO 459, Quinto Suplemento, 26-may-2021) y Reglamento (Decreto 904, RO 435). Artículos en C1 v0.2
A25: S1-T20 | B25: 46312 | C25: =B25 | D25: Buscar la versión validada en español de la escala SUS, para medir la usabilidad correctamente | E25: Víctor | F25: 02_Fuentes/Metodologia/ | G25: Ficha verificada + encuesta I1 v0.2 con la traducción | H25: Traducción con fuente | I25: 1 | J25: 46313 | K25: Hecho | L25: =IF(K25="Cancelado","",IF(J25<>"",J25-B25,IF(AND(K25<>"Hecho",TODAY()>B25),TODAY()-B25,0))) | M25: S1-02 (#2) | N25: Sevilla-Gonzalez et al. (2020), JMIR Human Factors: α = 0,812. Falta el umbral 68 (Lewis y Sauro 2018, PDF a mano)
A26: S1-T21 | B26: 46312 | C26: =B26 | D26: Buscar fuentes de metodología (DSR, Design Thinking, Scrum, censo), para justificar el método | E26: Víctor | F26: 02_Fuentes/Metodologia/ | G26: ≥6 fichas | H26: Cada método con 2–3 fuentes | I26: 1.5 | K26: En curso | L26: =IF(K26="Cancelado","",IF(J26<>"",J26-B26,IF(AND(K26<>"Hecho",TODAY()>B26),TODAY()-B26,0))) | M26: S1-02 (#2) | N26: Verificadas: Guía Scrum 2020, Sassa 2023, Tuunanen 2024 (DSR), Dawadi 2021 (mixto), Cuadrado Torres 2023 (DT). Falta: censo (Hernández-Sampieri), DT teórico (Auernhammer 2021)
A27: S1-T22 | B27: 46312 | C27: =B27 | D27: Investigar flujos de información y diseño de procesos (BPMN), para dibujar el proceso de Torvesa | E27: Diego | F27: 02_Fuentes/Metodologia/ | G27: ≥5 fichas | H27: Cada ficha dice qué respalda | I27: 1.5 | J27: 46320 | K27: Hecho | L27: =IF(K27="Cancelado","",IF(J27<>"",J27-B27,IF(AND(K27<>"Hecho",TODAY()>B27),TODAY()-B27,0))) | M27: S1-14 (#55) | N27: Movido a la semana 19–24 oct (bloques dobles de Diego en IA_DIEGO.md) · 25-oct: 6 fichas verificadas de BPMN y procesos, incluida la especificación OMG
A28: S1-T23 | B28: 46312 | C28: =B28 | D28: Investigar CRMs móviles y herramientas existentes con sus precios, para comparar y calcular costos | E28: Diego | F28: 02_Fuentes/Casos_Estudio/ y 02_Fuentes/Costos_Viabilidad/ | G28: Tabla de ≥6 herramientas con precio y fecha | H28: Cada precio con enlace oficial | I28: 2 | J28: 46320 | K28: Hecho | L28: =IF(K28="Cancelado","",IF(J28<>"",J28-B28,IF(AND(K28<>"Hecho",TODAY()>B28),TODAY()-B28,0))) | M28: S1-15 (#56) | N28: Movido a la semana 19–24 oct (bloques dobles de Diego en IA_DIEGO.md) · 25-oct: fichas de precios de CRM, mensajería, bóveda y LLM (bloques G y H)
A29: S1-T24 | B29: 46313 | C29: =B29 | D29: Tabular y anonimizar los datos de campo, para que estén listos y sean confiables | E29: Ambos | F29: 05_Datos_Campo/LineaBase_2026-10/ | G29: CSV anonimizados + hashes + auditoría | H29: auditoria_pii.py dice 0 hallazgos | I29: 2 | K29: Movido | L29: =IF(K29="Cancelado","",IF(J29<>"",J29-B29,IF(AND(K29<>"Hecho",TODAY()>B29),TODAY()-B29,0))) | M29: S1-12 (#12) | N29: Movido: se aplica cuando Torvesa autorice (Diego consigue la información y los permisos). Al día siguiente del campo · 27-oct: bloqueada, sin datos de campo; se hace al día siguiente del campo (S4-T16)
A30: S1-T25 | B30: 46313 | C30: =B30 | D30: Escribir un resumen de 1 página para Diego sobre el problema y sus fuentes | E30: Víctor | F30: 02_Fuentes/Problema/ | G30: 02_Fuentes/Problema/2026-10-18_Resumen_Problema.md | H30: Diego lo leyó | I30: 0.5 | J30: 46313 | K30: Hecho | L30: =IF(K30="Cancelado","",IF(J30<>"",J30-B30,IF(AND(K30<>"Hecho",TODAY()>B30),TODAY()-B30,0))) | M30: S1-01 (#1) | N30: Borrador de Claude en 02_Fuentes/Problema/2026-10-18_Resumen_Problema.md; falta que Víctor lo revise
A31: S1-T26 | B31: 46313 | C31: =B31 | D31: Escribir un resumen de 1 página para Víctor sobre CRMs y flujos | E31: Diego | F31: 02_Fuentes/Casos_Estudio/ | G31: 02_Fuentes/Casos_Estudio/2026-10-18_Resumen_CRM_Flujos.md | H31: Víctor lo leyó | I31: 0.5 | J31: 46320 | K31: Hecho | L31: =IF(K31="Cancelado","",IF(J31<>"",J31-B31,IF(AND(K31<>"Hecho",TODAY()>B31),TODAY()-B31,0))) | M31: S1-15 (#56) | N31: Movido a la semana 19–24 oct (bloques dobles de Diego en IA_DIEGO.md) · 25-oct: 02_Fuentes/Casos_Estudio/2026-10-25_Resumen_CRM_Flujos.md
A32: S1-T27 | B32: 46313 | C32: =B32 | D32: Revisar el sprint (qué hicimos, qué no, qué aprendimos), hacer 20 min de «explícame lo tuyo» y planificar el siguiente | E32: Ambos | F32: Llamada Víctor–Diego · 11_Planificacion/Bitacora_Semanal.md y 11_Planificacion/Cronograma_Tesis.xlsx | G32: Sección de la semana en la bitácora + hoja del sprint siguiente ajustada | H32: El informe del domingo (21:00) sale con la sección nueva | I32: 1 | K32: En curso | L32: =IF(K32="Cancelado","",IF(J32<>"",J32-B32,IF(AND(K32<>"Hecho",TODAY()>B32),TODAY()-B32,0))) | M32: S1-16 (#57) | N32: Revisión del sprint hecha por Víctor y Claude el 18-oct; falta la llamada de 20 min con Diego

Sheet Carga
A1: Carga por persona y día
A2: Rojo = más horas que el límite (2 h entre semana, 4 h fin de semana) o más de 4 tareas
A4: Fecha | B4: Día | C4: Límite (h) | D4: Horas Víctor | E4: Horas Diego | F4: Tareas Víctor | G4: Tareas Diego
A5: 46307 | B5: =A5 | C5: =IF(WEEKDAY(A5,2)>5,4,2) | D5: =SUMIFS('S1'!$I$6:$I$32,'S1'!$B$6:$B$32,$A5,'S1'!$E$6:$E$32,"Víctor")+SUMIFS('S1'!$I$6:$I$32,'S1'!$B$6:$B$32,$A5,'S1'!$E$6:$E$32,"Ambos")+SUMIFS('S2'!$I$6:$I$23,'S2'!$B$6:$B$23,$A5,'S2'!$E$6:$E$23,"Víctor")+SUMIFS('S2'!$I$6:$I$23,'S2'!$B$6:$B$23,$A5,'S2'!$E$6:$E$23,"Ambos")+SUMIFS('S3'!$I$6:$I$24,'S3'!$B$6:$B$24,$A5,'S3'!$E$6:$E$24,"Víctor")+SUMIFS('S3'!$I$6:$I$24,'S3'!$B$6:$B$24,$A5,'S3'!$E$6:$E$24,"Ambos")+SUMIFS('S4'!$I$6:$I$22,'S4'!$B$6:$B$22,$A5,'S4'!$E$6:$E$22,"Víctor")+SUMIFS('S4'!$I$6:$I$22,'S4'!$B$6:$B$22,$A5,'S4'!$E$6:$E$22,"Ambos")+SUMIFS('S5'!$I$6:$I$20,'S5'!$B$6:$B$20,$A5,'S5'!$E$6:$E$20,"Víctor")+SUMIFS('S5'!$I$6:$I$20,'S5'!$B$6:$B$20,$A5,'S5'!$E$6:$E$20,"Ambos")+SUMIFS('S6'!$I$6:$I$17,'S6'!$B$6:$B$17,$A5,'S6'!$E$6:$E$17,"Víctor")+SUMIFS('S6'!$I$6:$I$17,'S6'!$B$6:$B$17,$A5,'S6'!$E$6:$E$17,"Ambos")+SUMIFS('S7'!$I$6:$I$19,'S7'!$B$6:$B$19,$A5,'S7'!$E$6:$E$19,"Víctor")+SUMIFS('S7'!$I$6:$I$19,'S7'!$B$6:$B$19,$A5,'S7'!$E$6:$E$19,"Ambos")+SUMIFS('S8'!$I$6:$I$23,'S8'!$B$6:$B$23,$A5,'S8'!$E$6:$E$23,"Víctor")+SUMIFS('S8'!$I$6:$I$23,'S8'!$B$6:$B$23,$A5,'S8'!$E$6:$E$23,"Ambos")+SUMIFS('S9'!$I$6:$I$15,'S9'!$B$6:$B$15,$A5,'S9'!$E$6:$E$15,"Víctor")+SUMIFS('S9'!$I$6:$I$15,'S9'!$B$6:$B$15,$A5,'S9'!$E$6:$E$15,"Ambos")+SUMIFS('S10'!$I$6:$I$13,'S10'!$B$6:$B$13,$A5,'S10'!$E$6:$E$13,"Víctor")+SUMIFS('S10'!$I$6:$I$13,'S10'!$B$6:$B$13,$A5,'S10'!$E$6:$E$13,"Ambos")+SUMIFS('Holgura'!$I$6:$I$11,'Holgura'!$B$6:$B$11,$A5,'Holgura'!$E$6:$E$11,"Víctor")+SUMIFS('Holgura'!$I$6:$I$11,'Holgura'!$B$6:$B$11,$A5,'Holgura'!$E$6:$E$11,"Ambos")+SUMIFS('Entrega'!$I$6:$I$9,'Entrega'!$B$6:$B$9,$A5,'Entrega'!$E$6:$E$9,"Víctor")+SUMIFS('Entrega'!$I$6:$I$9,'Entrega'!$B$6:$B$9,$A5,'Entrega'!$E$6:$E$9,"Ambos")+SUMIFS('Defensa'!$I$6:$I$10,'Defensa'!$B$6:$B$10,$A5,'Defensa'!$E$6:$E$10,"Víctor")+SUMIFS('Defensa'!$I$6:$I$10,'Defensa'!$B$6:$B$10,$A5,'Defensa'!$E$6:$E$10,"Ambos") | E5: =SUMIFS('S1'!$I$6:$I$32,'S1'!$B$6:$B$32,$A5,'S1'!$E$6:$E$32,"Diego")+SUMIFS('S1'!$I$6:$I$32,'S1'!$B$6:$B$32,$A5,'S1'!$E$6:$E$32,"Ambos")+SUMIFS('S2'!$I$6:$I$23,'S2'!$B$6:$B$23,$A5,'S2'!$E$6:$E$23,"Diego")+SUMIFS('S2'!$I$6:$I$23,'S2'!$B$6:$B$23,$A5,'S2'!$E$6:$E$23,"Ambos")+SUMIFS('S3'!$I$6:$I$24,'S3'!$B$6:$B$24,$A5,'S3'!$E$6:$E$24,"Diego")+SUMIFS('S3'!$I$6:$I$24,'S3'!$B$6:$B$24,$A5,'S3'!$E$6:$E$24,"Ambos")+SUMIFS('S4'!$I$6:$I$22,'S4'!$B$6:$B$22,$A5,'S4'!$E$6:$E$22,"Diego")+SUMIFS('S4'!$I$6:$I$22,'S4'!$B$6:$B$22,$A5,'S4'!$E$6:$E$22,"Ambos")+SUMIFS('S5'!$I$6:$I$20,'S5'!$B$6:$B$20,$A5,'S5'!$E$6:$E$20,"Diego")+SUMIFS('S5'!$I$6:$I$20,'S5'!$B$6:$B$20,$A5,'S5'!$E$6:$E$20,"Ambos")+SUMIFS('S6'!$I$6:$I$17,'S6'!$B$6:$B$17,$A5,'S6'!$E$6:$E$17,"Diego")+SUMIFS('S6'!$I$6:$I$17,'S6'!$B$6:$B$17,$A5,'S6'!$E$6:$E$17,"Ambos")+SUMIFS('S7'!$I$6:$I$19,'S7'!$B$6:$B$19,$A5,'S7'!$E$6:$E$19,"Diego")+SUMIFS('S7'!$I$6:$I$19,'S7'!$B$6:$B$19,$A5,'S7'!$E$6:$E$19,"Ambos")+SUMIFS('S8'!$I$6:$I$23,'S8'!$B$6:$B$23,$A5,'S8'!$E$6:$E$23,"Diego")+SUMIFS('S8'!$I$6:$I$23,'S8'!$B$6:$B$23,$A5,'S8'!$E$6:$E$23,"Ambos")+SUMIFS('S9'!$I$6:$I$15,'S9'!$B$6:$B$15,$A5,'S9'!$E$6:$E$15,"Diego")+SUMIFS('S9'!$I$6:$I$15,'S9'!$B$6:$B$15,$A5,'S9'!$E$6:$E$15,"Ambos")+SUMIFS('S10'!$I$6:$I$13,'S10'!$B$6:$B$13,$A5,'S10'!$E$6:$E$13,"Diego")+SUMIFS('S10'!$I$6:$I$13,'S10'!$B$6:$B$13,$A5,'S10'!$E$6:$E$13,"Ambos")+SUMIFS('Holgura'!$I$6:$I$11,'Holgura'!$B$6:$B$11,$A5,'Holgura'!$E$6:$E$11,"Diego")+SUMIFS('Holgura'!$I$6:$I$11,'Holgura'!$B$6:$B$11,$A5,'Holgura'!$E$6:$E$11,"Ambos")+SUMIFS('Entrega'!$I$6:$I$9,'Entrega'!$B$6:$B$9,$A5,'Entrega'!$E$6:$E$9,"Diego")+SUMIFS('Entrega'!$I$6:$I$9,'Entrega'!$B$6:$B$9,$A5,'Entrega'!$E$6:$E$9,"Ambos")+SUMIFS('Defensa'!$I$6:$I$10,'Defensa'!$B$6:$B$10,$A5,'Defensa'!$E$6:$E$10,"Diego")+SUMIFS('Defensa'!$I$6:$I$10,'Defensa'!$B$6:$B$10,$A5,'Defensa'!$E$6:$E$10,"Ambos") | F5: =COUNTIFS('S1'!$B$6:$B$32,$A5,'S1'!$E$6:$E$32,"Víctor")+COUNTIFS('S1'!$B$6:$B$32,$A5,'S1'!$E$6:$E$32,"Ambos")+COUNTIFS('S2'!$B$6:$B$23,$A5,'S2'!$E$6:$E$23,"Víctor")+COUNTIFS('S2'!$B$6:$B$23,$A5,'S2'!$E$6:$E$23,"Ambos")+COUNTIFS('S3'!$B$6:$B$24,$A5,'S3'!$E$6:$E$24,"Víctor")+COUNTIFS('S3'!$B$6:$B$24,$A5,'S3'!$E$6:$E$24,"Ambos")+COUNTIFS('S4'!$B$6:$B$22,$A5,'S4'!$E$6:$E$22,"Víctor")+COUNTIFS('S4'!$B$6:$B$22,$A5,'S4'!$E$6:$E$22,"Ambos")+COUNTIFS('S5'!$B$6:$B$20,$A5,'S5'!$E$6:$E$20,"Víctor")+COUNTIFS('S5'!$B$6:$B$20,$A5,'S5'!$E$6:$E$20,"Ambos")+COUNTIFS('S6'!$B$6:$B$17,$A5,'S6'!$E$6:$E$17,"Víctor")+COUNTIFS('S6'!$B$6:$B$17,$A5,'S6'!$E$6:$E$17,"Ambos")+COUNTIFS('S7'!$B$6:$B$19,$A5,'S7'!$E$6:$E$19,"Víctor")+COUNTIFS('S7'!$B$6:$B$19,$A5,'S7'!$E$6:$E$19,"Ambos")+COUNTIFS('S8'!$B$6:$B$23,$A5,'S8'!$E$6:$E$23,"Víctor")+COUNTIFS('S8'!$B$6:$B$23,$A5,'S8'!$E$6:$E$23,"Ambos")+COUNTIFS('S9'!$B$6:$B$15,$A5,'S9'!$E$6:$E$15,"Víctor")+COUNTIFS('S9'!$B$6:$B$15,$A5,'S9'!$E$6:$E$15,"Ambos")+COUNTIFS('S10'!$B$6:$B$13,$A5,'S10'!$E$6:$E$13,"Víctor")+COUNTIFS('S10'!$B$6:$B$13,$A5,'S10'!$E$6:$E$13,"Ambos")+COUNTIFS('Holgura'!$B$6:$B$11,$A5,'Holgura'!$E$6:$E$11,"Víctor")+COUNTIFS('Holgura'!$B$6:$B$11,$A5,'Holgura'!$E$6:$E$11,"Ambos")+COUNTIFS('Entrega'!$B$6:$B$9,$A5,'Entrega'!$E$6:$E$9,"Víctor")+COUNTIFS('Entrega'!$B$6:$B$9,$A5,'Entrega'!$E$6:$E$9,"Ambos")+COUNTIFS('Defensa'!$B$6:$B$10,$A5,'Defensa'!$E$6:$E$10,"Víctor")+COUNTIFS('Defensa'!$B$6:$B$10,$A5,'Defensa'!$E$6:$E$10,"Ambos") | G5: =COUNTIFS('S1'!$B$6:$B$32,$A5,'S1'!$E$6:$E$32,"Diego")+COUNTIFS('S1'!$B$6:$B$32,$A5,'S1'!$E$6:$E$32,"Ambos")+COUNTIFS('S2'!$B$6:$B$23,$A5,'S2'!$E$6:$E$23,"Diego")+COUNTIFS('S2'!$B$6:$B$23,$A5,'S2'!$E$6:$E$23,"Ambos")+COUNTIFS('S3'!$B$6:$B$24,$A5,'S3'!$E$6:$E$24,"Diego")+COUNTIFS('S3'!$B$6:$B$24,$A5,'S3'!$E$6:$E$24,"Ambos")+COUNTIFS('S4'!$B$6:$B$22,$A5,'S4'!$E$6:$E$22,"Diego")+COUNTIFS('S4'!$B$6:$B$22,$A5,'S4'!$E$6:$E$22,"Ambos")+COUNTIFS('S5'!$B$6:$B$20,$A5,'S5'!$E$6:$E$20,"Diego")+COUNTIFS('S5'!$B$6:$B$20,$A5,'S5'!$E$6:$E$20,"Ambos")+COUNTIFS('S6'!$B$6:$B$17,$A5,'S6'!$E$6:$E$17,"Diego")+COUNTIFS('S6'!$B$6:$B$17,$A5,'S6'!$E$6:$E$17,"Ambos")+COUNTIFS('S7'!$B$6:$B$19,$A5,'S7'!$E$6:$E$19,"Diego")+COUNTIFS('S7'!$B$6:$B$19,$A5,'S7'!$E$6:$E$19,"Ambos")+COUNTIFS('S8'!$B$6:$B$23,$A5,'S8'!$E$6:$E$23,"Diego")+COUNTIFS('S8'!$B$6:$B$23,$A5,'S8'!$E$6:$E$23,"Ambos")+COUNTIFS('S9'!$B$6:$B$15,$A5,'S9'!$E$6:$E$15,"Diego")+COUNTIFS('S9'!$B$6:$B$15,$A5,'S9'!$E$6:$E$15,"Ambos")+COUNTIFS('S10'!$B$6:$B$13,$A5,'S10'!$E$6:$E$13,"Diego")+COUNTIFS('S10'!$B$6:$B$13,$A5,'S10'!$E$6:$E$13,"Ambos")+COUNTIFS('Holgura'!$B$6:$B$11,$A5,'Holgura'!$E$6:$E$11,"Diego")+COUNTIFS('Holgura'!$B$6:$B$11,$A5,'Holgura'!$E$6:$E$11,"Ambos")+COUNTIFS('Entrega'!$B$6:$B$9,$A5,'Entrega'!$E$6:$E$9,"Diego")+COUNTIFS('Entrega'!$B$6:$B$9,$A5,'Entrega'!$E$6:$E$9,"Ambos")+COUNTIFS('Defensa'!$B$6:$B$10,$A5,'Defensa'!$E$6:$E$10,"Diego")+COUNTIFS('Defensa'!$B$6:$B$10,$A5,'Defensa'!$E$6:$E$10,"Ambos")
A6: 46308 | B6: =A6 | C6: =IF(WEEKDAY(A6,2)>5,4,2) | D6: =SUMIFS('S1'!$I$6:$I$32,'S1'!$B$6:$B$32,$A6,'S1'!$E$6:$E$32,"Víctor")+SUMIFS('S1'!$I$6:$I$32,'S1'!$B$6:$B$32,$A6,'S1'!$E$6:$E$32,"Ambos")+SUMIFS('S2'!$I$6:$I$23,'S2'!$B$6:$B$23,$A6,'S2'!$E$6:$E$23,"Víctor")+SUMIFS('S2'!$I$6:$I$23,'S2'!$B$6:$B$23,$A6,'S2'!$E$6:$E$23,"Ambos")+SUMIFS('S3'!$I$6:$I$24,'S3'!$B$6:$B$24,$A6,'S3'!$E$6:$E$24,"Víctor")+SUMIFS('S3'!$I$6:$I$24,'S3'!$B$6:$B$24,$A6,'S3'!$E$6:$E$24,"Ambos")+SUMIFS('S4'!$I$6:$I$22,'S4'!$B$6:$B$22,$A6,'S4'!$E$6:$E$22,"Víctor")+SUMIFS('S4'!$I$6:$I$22,'S4'!$B$6:$B$22,$A6,'S4'!$E$6:$E$22,"Ambos")+SUMIFS('S5'!$I$6:$I$20,'S5'!$B$6:$B$20,$A6,'S5'!$E$6:$E$20,"Víctor")+SUMIFS('S5'!$I$6:$I$20,'S5'!$B$6:$B$20,$A6,'S5'!$E$6:$E$20,"Ambos")+SUMIFS('S6'!$I$6:$I$17,'S6'!$B$6:$B$17,$A6,'S6'!$E$6:$E$17,"Víctor")+SUMIFS('S6'!$I$6:$I$17,'S6'!$B$6:$B$17,$A6,'S6'!$E$6:$E$17,"Ambos")+SUMIFS('S7'!$I$6:$I$19,'S7'!$B$6:$B$19,$A6,'S7'!$E$6:$E$19,"Víctor")+SUMIFS('S7'!$I$6:$I$19,'S7'!$B$6:$B$19,$A6,'S7'!$E$6:$E$19,"Ambos")+SUMIFS('S8'!$I$6:$I$23,'S8'!$B$6:$B$23,$A6,'S8'!$E$6:$E$23,"Víctor")+SUMIFS('S8'!$I$6:$I$23,'S8'!$B$6:$B$23,$A6,'S8'!$E$6:$E$23,"Ambos")+SUMIFS('S9'!$I$6:$I$15,'S9'!$B$6:$B$15,$A6,'S9'!$E$6:$E$15,"Víctor")+SUMIFS('S9'!$I$6:$I$15,'S9'!$B$6:$B$15,$A6,'S9'!$E$6:$E$15,"Ambos")+SUMIFS('S10'!$I$6:$I$13,'S10'!$B$6:$B$13,$A6,'S10'!$E$6:$E$13,"Víctor")+SUMIFS('S10'!$I$6:$I$13,'S10'!$B$6:$B$13,$A6,'S10'!$E$6:$E$13,"Ambos")+SUMIFS('Holgura'!$I$6:$I$11,'Holgura'!$B$6:$B$11,$A6,'Holgura'!$E$6:$E$11,"Víctor")+SUMIFS('Holgura'!$I$6:$I$11,'Holgura'!$B$6:$B$11,$A6,'Holgura'!$E$6:$E$11,"Ambos")+SUMIFS('Entrega'!$I$6:$I$9,'Entrega'!$B$6:$B$9,$A6,'Entrega'!$E$6:$E$9,"Víctor")+SUMIFS('Entrega'!$I$6:$I$9,'Entrega'!$B$6:$B$9,$A6,'Entrega'!$E$6:$E$9,"Ambos")+SUMIFS('Defensa'!$I$6:$I$10,'Defensa'!$B$6:$B$10,$A6,'Defensa'!$E$6:$E$10,"Víctor")+SUMIFS('Defensa'!$I$6:$I$10,'Defensa'!$B$6:$B$10,$A6,'Defensa'!$E$6:$E$10,"Ambos") | E6: =SUMIFS('S1'!$I$6:$I$32,'S1'!$B$6:$B$32,$A6,'S1'!$E$6:$E$32,"Diego")+SUMIFS('S1'!$I$6:$I$32,'S1'!$B$6:$B$32,$A6,'S1'!$E$6:$E$32,"Ambos")+SUMIFS('S2'!$I$6:$I$23,'S2'!$B$6:$B$23,$A6,'S2'!$E$6:$E$23,"Diego")+SUMIFS('S2'!$I$6:$I$23,'S2'!$B$6:$B$23,$A6,'S2'!$E$6:$E$23,"Ambos")+SUMIFS('S3'!$I$6:$I$24,'S3'!$B$6:$B$24,$A6,'S3'!$E$6:$E$24,"Diego")+SUMIFS('S3'!$I$6:$I$24,'S3'!$B$6:$B$24,$A6,'S3'!$E$6:$E$24,"Ambos")+SUMIFS('S4'!$I$6:$I$22,'S4'!$B$6:$B$22,$A6,'S4'!$E$6:$E$22,"Diego")+SUMIFS('S4'!$I$6:$I$22,'S4'!$B$6:$B$22,$A6,'S4'!$E$6:$E$22,"Ambos")+SUMIFS('S5'!$I$6:$I$20,'S5'!$B$6:$B$20,$A6,'S5'!$E$6:$E$20,"Diego")+SUMIFS('S5'!$I$6:$I$20,'S5'!$B$6:$B$20,$A6,'S5'!$E$6:$E$20,"Ambos")+SUMIFS('S6'!$I$6:$I$17,'S6'!$B$6:$B$17,$A6,'S6'!$E$6:$E$17,"Diego")+SUMIFS('S6'!$I$6:$I$17,'S6'!$B$6:$B$17,$A6,'S6'!$E$6:$E$17,"Ambos")+SUMIFS('S7'!$I$6:$I$19,'S7'!$B$6:$B$19,$A6,'S7'!$E$6:$E$19,"Diego")+SUMIFS('S7'!$I$6:$I$19,'S7'!$B$6:$B$19,$A6,'S7'!$E$6:$E$19,"Ambos")+SUMIFS('S8'!$I$6:$I$23,'S8'!$B$6:$B$23,$A6,'S8'!$E$6:$E$23,"Diego")+SUMIFS('S8'!$I$6:$I$23,'S8'!$B$6:$B$23,$A6,'S8'!$E$6:$E$23,"Ambos")+SUMIFS('S9'!$I$6:$I$15,'S9'!$B$6:$B$15,$A6,'S9'!$E$6:$E$15,"Diego")+SUMIFS('S9'!$I$6:$I$15,'S9'!$B$6:$B$15,$A6,'S9'!$E$6:$E$15,"Ambos")+SUMIFS('S10'!$I$6:$I$13,'S10'!$B$6:$B$13,$A6,'S10'!$E$6:$E$13,"Diego")+SUMIFS('S10'!$I$6:$I$13,'S10'!$B$6:$B$13,$A6,'S10'!$E$6:$E$13,"Ambos")+SUMIFS('Holgura'!$I$6:$I$11,'Holgura'!$B$6:$B$11,$A6,'Holgura'!$E$6:$E$11,"Diego")+SUMIFS('Holgura'!$I$6:$I$11,'Holgura'!$B$6:$B$11,$A6,'Holgura'!$E$6:$E$11,"Ambos")+SUMIFS('Entrega'!$I$6:$I$9,'Entrega'!$B$6:$B$9,$A6,'Entrega'!$E$6:$E$9,"Diego")+SUMIFS('Entrega'!$I$6:$I$9,'Entrega'!$B$6:$B$9,$A6,'Entrega'!$E$6:$E$9,"Ambos")+SUMIFS('Defensa'!$I$6:$I$10,'Defensa'!$B$6:$B$10,$A6,'Defensa'!$E$6:$E$10,"Diego")+SUMIFS('Defensa'!$I$6:$I$10,'Defensa'!$B$6:$B$10,$A6,'Defensa'!$E$6:$E$10,"Ambos") | F6: =COUNTIFS('S1'!$B$6:$B$32,$A6,'S1'!$E$6:$E$32,"Víctor")+COUNTIFS('S1'!$B$6:$B$32,$A6,'S1'!$E$6:$E$32,"Ambos")+COUNTIFS('S2'!$B$6:$B$23,$A6,'S2'!$E$6:$E$23,"Víctor")+COUNTIFS('S2'!$B$6:$B$23,$A6,'S2'!$E$6:$E$23,"Ambos")+COUNTIFS('S3'!$B$6:$B$24,$A6,'S3'!$E$6:$E$24,"Víctor")+COUNTIFS('S3'!$B$6:$B$24,$A6,'S3'!$E$6:$E$24,"Ambos")+COUNTIFS('S4'!$B$6:$B$22,$A6,'S4'!$E$6:$E$22,"Víctor")+COUNTIFS('S4'!$B$6:$B$22,$A6,'S4'!$E$6:$E$22,"Ambos")+COUNTIFS('S5'!$B$6:$B$20,$A6,'S5'!$E$6:$E$20,"Víctor")+COUNTIFS('S5'!$B$6:$B$20,$A6,'S5'!$E$6:$E$20,"Ambos")+COUNTIFS('S6'!$B$6:$B$17,$A6,'S6'!$E$6:$E$17,"Víctor")+COUNTIFS('S6'!$B$6:$B$17,$A6,'S6'!$E$6:$E$17,"Ambos")+COUNTIFS('S7'!$B$6:$B$19,$A6,'S7'!$E$6:$E$19,"Víctor")+COUNTIFS('S7'!$B$6:$B$19,$A6,'S7'!$E$6:$E$19,"Ambos")+COUNTIFS('S8'!$B$6:$B$23,$A6,'S8'!$E$6:$E$23,"Víctor")+COUNTIFS('S8'!$B$6:$B$23,$A6,'S8'!$E$6:$E$23,"Ambos")+COUNTIFS('S9'!$B$6:$B$15,$A6,'S9'!$E$6:$E$15,"Víctor")+COUNTIFS('S9'!$B$6:$B$15,$A6,'S9'!$E$6:$E$15,"Ambos")+COUNTIFS('S10'!$B$6:$B$13,$A6,'S10'!$E$6:$E$13,"Víctor")+COUNTIFS('S10'!$B$6:$B$13,$A6,'S10'!$E$6:$E$13,"Ambos")+COUNTIFS('Holgura'!$B$6:$B$11,$A6,'Holgura'!$E$6:$E$11,"Víctor")+COUNTIFS('Holgura'!$B$6:$B$11,$A6,'Holgura'!$E$6:$E$11,"Ambos")+COUNTIFS('Entrega'!$B$6:$B$9,$A6,'Entrega'!$E$6:$E$9,"Víctor")+COUNTIFS('Entrega'!$B$6:$B$9,$A6,'Entrega'!$E$6:$E$9,"Ambos")+COUNTIFS('Defensa'!$B$6:$B$10,$A6,'Defensa'!$E$6:$E$10,"Víctor")+COUNTIFS('Defensa'!$B$6:$B$10,$A6,'Defensa'!$E$6:$E$10,"Ambos") | G6: =COUNTIFS('S1'!$B$6:$B$32,$A6,'S1'!$E$6:$E$32,"Diego")+COUNTIFS('S1'!$B$6:$B$32,$A6,'S1'!$E$6:$E$32,"Ambos")+COUNTIFS('S2'!$B$6:$B$23,$A6,'S2'!$E$6:$E$23,"Diego")+COUNTIFS('S2'!$B$6:$B$23,$A6,'S2'!$E$6:$E$23,"Ambos")+COUNTIFS('S3'!$B$6:$B$24,$A6,'S3'!$E$6:$E$24,"Diego")+COUNTIFS('S3'!$B$6:$B$24,$A6,'S3'!$E$6:$E$24,"Ambos")+COUNTIFS('S4'!$B$6:$B$22,$A6,'S4'!$E$6:$E$22,"Diego")+COUNTIFS('S4'!$B$6:$B$22,$A6,'S4'!$E$6:$E$22,"Ambos")+COUNTIFS('S5'!$B$6:$B$20,$A6,'S5'!$E$6:$E$20,"Diego")+COUNTIFS('S5'!$B$6:$B$20,$A6,'S5'!$E$6:$E$20,"Ambos")+COUNTIFS('S6'!$B$6:$B$17,$A6,'S6'!$E$6:$E$17,"Diego")+COUNTIFS('S6'!$B$6:$B$17,$A6,'S6'!$E$6:$E$17,"Ambos")+COUNTIFS('S7'!$B$6:$B$19,$A6,'S7'!$E$6:$E$19,"Diego")+COUNTIFS('S7'!$B$6:$B$19,$A6,'S7'!$E$6:$E$19,"Ambos")+COUNTIFS('S8'!$B$6:$B$23,$A6,'S8'!$E$6:$E$23,"Diego")+COUNTIFS('S8'!$B$6:$B$23,$A6,'S8'!$E$6:$E$23,"Ambos")+COUNTIFS('S9'!$B$6:$B$15,$A6,'S9'!$E$6:$E$15,"Diego")+COUNTIFS('S9'!$B$6:$B$15,$A6,'S9'!$E$6:$E$15,"Ambos")+COUNTIFS('S10'!$B$6:$B$13,$A6,'S10'!$E$6:$E$13,"Diego")+COUNTIFS('S10'!$B$6:$B$13,$A6,'S10'!$E$6:$E$13,"Ambos")+COUNTIFS('Holgura'!$B$6:$B$11,$A6,'Holgura'!$E$6:$E$11,"Diego")+COUNTIFS('Holgura'!$B$6:$B$11,$A6,'Holgura'!$E$6:$E$11,"Ambos")+COUNTIFS('Entrega'!$B$6:$B$9,$A6,'Entrega'!$E$6:$E$9,"Diego")+COUNTIFS('Entrega'!$B$6:$B$9,$A6,'Entrega'!$E$6:$E$9,"Ambos")+COUNTIFS('Defensa'!$B$6:$B$10,$A6,'Defensa'!$E$6:$E$10,"Diego")+COUNTIFS('Defensa'!$B$6:$B$10,$A6,'Defensa'!$E$6:$E$10,"Ambos")
A7: 46309 | B7: =A7 | C7: =IF(WEEKDAY(A7,2)>5,4,2) | D7: =SUMIFS('S1'!$I$6:$I$32,'S1'!$B$6:$B$32,$A7,'S1'!$E$6:$E$32,"Víctor")+SUMIFS('S1'!$I$6:$I$32,'S1'!$B$6:$B$32,$A7,'S1'!$E$6:$E$32,"Ambos")+SUMIFS('S2'!$I$6:$I$23,'S2'!$B$6:$B$23,$A7,'S2'!$E$6:$E$23,"Víctor")+SUMIFS('S2'!$I$6:$I$23,'S2'!$B$6:$B$23,$A7,'S2'!$E$6:$E$23,"Ambos")+SUMIFS('S3'!$I$6:$I$24,'S3'!$B$6:$B$24,$A7,'S3'!$E$6:$E$24,"Víctor")+SUMIFS('S3'!$I$6:$I$24,'S3'!$B$6:$B$24,$A7,'S3'!$E$6:$E$24,"Ambos")+SUMIFS('S4'!$I$6:$I$22,'S4'!$B$6:$B$22,$A7,'S4'!$E$6:$E$22,"Víctor")+SUMIFS('S4'!$I$6:$I$22,'S4'!$B$6:$B$22,$A7,'S4'!$E$6:$E$22,"Ambos")+SUMIFS('S5'!$I$6:$I$20,'S5'!$B$6:$B$20,$A7,'S5'!$E$6:$E$20,"Víctor")+SUMIFS('S5'!$I$6:$I$20,'S5'!$B$6:$B$20,$A7,'S5'!$E$6:$E$20,"Ambos")+SUMIFS('S6'!$I$6:$I$17,'S6'!$B$6:$B$17,$A7,'S6'!$E$6:$E$17,"Víctor")+SUMIFS('S6'!$I$6:$I$17,'S6'!$B$6:$B$17,$A7,'S6'!$E$6:$E$17,"Ambos")+SUMIFS('S7'!$I$6:$I$19,'S7'!$B$6:$B$19,$A7,'S7'!$E$6:$E$19,"Víctor")+SUMIFS('S7'!$I$6:$I$19,'S7'!$B$6:$B$19,$A7,'S7'!$E$6:$E$19,"Ambos")+SUMIFS('S8'!$I$6:$I$23,'S8'!$B$6:$B$23,$A7,'S8'!$E$6:$E$23,"Víctor")+SUMIFS('S8'!$I$6:$I$23,'S8'!$B$6:$B$23,$A7,'S8'!$E$6:$E$23,"Ambos")+SUMIFS('S9'!$I$6:$I$15,'S9'!$B$6:$B$15,$A7,'S9'!$E$6:$E$15,"Víctor")+SUMIFS('S9'!$I$6:$I$15,'S9'!$B$6:$B$15,$A7,'S9'!$E$6:$E$15,"Ambos")+SUMIFS('S10'!$I$6:$I$13,'S10'!$B$6:$B$13,$A7,'S10'!$E$6:$E$13,"Víctor")+SUMIFS('S10'!$I$6:$I$13,'S10'!$B$6:$B$13,$A7,'S10'!$E$6:$E$13,"Ambos")+SUMIFS('Holgura'!$I$6:$I$11,'Holgura'!$B$6:$B$11,$A7,'Holgura'!$E$6:$E$11,"Víctor")+SUMIFS('Holgura'!$I$6:$I$11,'Holgura'!$B$6:$B$11,$A7,'Holgura'!$E$6:$E$11,"Ambos")+SUMIFS('Entrega'!$I$6:$I$9,'Entrega'!$B$6:$B$9,$A7,'Entrega'!$E$6:$E$9,"Víctor")+SUMIFS('Entrega'!$I$6:$I$9,'Entrega'!$B$6:$B$9,$A7,'Entrega'!$E$6:$E$9,"Ambos")+SUMIFS('Defensa'!$I$6:$I$10,'Defensa'!$B$6:$B$10,$A7,'Defensa'!$E$6:$E$10,"Víctor")+SUMIFS('Defensa'!$I$6:$I$10,'Defensa'!$B$6:$B$10,$A7,'Defensa'!$E$6:$E$10,"Ambos") | E7: =SUMIFS('S1'!$I$6:$I$32,'S1'!$B$6:$B$32,$A7,'S1'!$E$6:$E$32,"Diego")+SUMIFS('S1'!$I$6:$I$32,'S1'!$B$6:$B$32,$A7,'S1'!$E$6:$E$32,"Ambos")+SUMIFS('S2'!$I$6:$I$23,'S2'!$B$6:$B$23,$A7,'S2'!$E$6:$E$23,"Diego")+SUMIFS('S2'!$I$6:$I$23,'S2'!$B$6:$B$23,$A7,'S2'!$E$6:$E$23,"Ambos")+SUMIFS('S3'!$I$6:$I$24,'S3'!$B$6:$B$24,$A7,'S3'!$E$6:$E$24,"Diego")+SUMIFS('S3'!$I$6:$I$24,'S3'!$B$6:$B$24,$A7,'S3'!$E$6:$E$24,"Ambos")+SUMIFS('S4'!$I$6:$I$22,'S4'!$B$6:$B$22,$A7,'S4'!$E$6:$E$22,"Diego")+SUMIFS('S4'!$I$6:$I$22,'S4'!$B$6:$B$22,$A7,'S4'!$E$6:$E$22,"Ambos")+SUMIFS('S5'!$I$6:$I$20,'S5'!$B$6:$B$20,$A7,'S5'!$E$6:$E$20,"Diego")+SUMIFS('S5'!$I$6:$I$20,'S5'!$B$6:$B$20,$A7,'S5'!$E$6:$E$20,"Ambos")+SUMIFS('S6'!$I$6:$I$17,'S6'!$B$6:$B$17,$A7,'S6'!$E$6:$E$17,"Diego")+SUMIFS('S6'!$I$6:$I$17,'S6'!$B$6:$B$17,$A7,'S6'!$E$6:$E$17,"Ambos")+SUMIFS('S7'!$I$6:$I$19,'S7'!$B$6:$B$19,$A7,'S7'!$E$6:$E$19,"Diego")+SUMIFS('S7'!$I$6:$I$19,'S7'!$B$6:$B$19,$A7,'S7'!$E$6:$E$19,"Ambos")+SUMIFS('S8'!$I$6:$I$23,'S8'!$B$6:$B$23,$A7,'S8'!$E$6:$E$23,"Diego")+SUMIFS('S8'!$I$6:$I$23,'S8'!$B$6:$B$23,$A7,'S8'!$E$6:$E$23,"Ambos")+SUMIFS('S9'!$I$6:$I$15,'S9'!$B$6:$B$15,$A7,'S9'!$E$6:$E$15,"Diego")+SUMIFS('S9'!$I$6:$I$15,'S9'!$B$6:$B$15,$A7,'S9'!$E$6:$E$15,"Ambos")+SUMIFS('S10'!$I$6:$I$13,'S10'!$B$6:$B$13,$A7,'S10'!$E$6:$E$13,"Diego")+SUMIFS('S10'!$I$6:$I$13,'S10'!$B$6:$B$13,$A7,'S10'!$E$6:$E$13,"Ambos")+SUMIFS('Holgura'!$I$6:$I$11,'Holgura'!$B$6:$B$11,$A7,'Holgura'!$E$6:$E$11,"Diego")+SUMIFS('Holgura'!$I$6:$I$11,'Holgura'!$B$6:$B$11,$A7,'Holgura'!$E$6:$E$11,"Ambos")+SUMIFS('Entrega'!$I$6:$I$9,'Entrega'!$B$6:$B$9,$A7,'Entrega'!$E$6:$E$9,"Diego")+SUMIFS('Entrega'!$I$6:$I$9,'Entrega'!$B$6:$B$9,$A7,'Entrega'!$E$6:$E$9,"Ambos")+SUMIFS('Defensa'!$I$6:$I$10,'Defensa'!$B$6:$B$10,$A7,'Defensa'!$E$6:$E$10,"Diego")+SUMIFS('Defensa'!$I$6:$I$10,'Defensa'!$B$6:$B$10,$A7,'Defensa'!$E$6:$E$10,"Ambos") | F7: =COUNTIFS('S1'!$B$6:$B$32,$A7,'S1'!$E$6:$E$32,"Víctor")+COUNTIFS('S1'!$B$6:$B$32,$A7,'S1'!$E$6:$E$32,"Ambos")+COUNTIFS('S2'!$B$6:$B$23,$A7,'S2'!$E$6:$E$23,"Víctor")+COUNTIFS('S2'!$B$6:$B$23,$A7,'S2'!$E$6:$E$23,"Ambos")+COUNTIFS('S3'!$B$6:$B$24,$A7,'S3'!$E$6:$E$24,"Víctor")+COUNTIFS('S3'!$B$6:$B$24,$A7,'S3'!$E$6:$E$24,"Ambos")+COUNTIFS('S4'!$B$6:$B$22,$A7,'S4'!$E$6:$E$22,"Víctor")+COUNTIFS('S4'!$B$6:$B$22,$A7,'S4'!$E$6:$E$22,"Ambos")+COUNTIFS('S5'!$B$6:$B$20,$A7,'S5'!$E$6:$E$20,"Víctor")+COUNTIFS('S5'!$B$6:$B$20,$A7,'S5'!$E$6:$E$20,"Ambos")+COUNTIFS('S6'!$B$6:$B$17,$A7,'S6'!$E$6:$E$17,"Víctor")+COUNTIFS('S6'!$B$6:$B$17,$A7,'S6'!$E$6:$E$17,"Ambos")+COUNTIFS('S7'!$B$6:$B$19,$A7,'S7'!$E$6:$E$19,"Víctor")+COUNTIFS('S7'!$B$6:$B$19,$A7,'S7'!$E$6:$E$19,"Ambos")+COUNTIFS('S8'!$B$6:$B$23,$A7,'S8'!$E$6:$E$23,"Víctor")+COUNTIFS('S8'!$B$6:$B$23,$A7,'S8'!$E$6:$E$23,"Ambos")+COUNTIFS('S9'!$B$6:$B$15,$A7,'S9'!$E$6:$E$15,"Víctor")+COUNTIFS('S9'!$B$6:$B$15,$A7,'S9'!$E$6:$E$15,"Ambos")+COUNTIFS('S10'!$B$6:$B$13,$A7,'S10'!$E$6:$E$13,"Víctor")+COUNTIFS('S10'!$B$6:$B$13,$A7,'S10'!$E$6:$E$13,"Ambos")+COUNTIFS('Holgura'!$B$6:$B$11,$A7,'Holgura'!$E$6:$E$11,"Víctor")+COUNTIFS('Holgura'!$B$6:$B$11,$A7,'Holgura'!$E$6:$E$11,"Ambos")+COUNTIFS('Entrega'!$B$6:$B$9,$A7,'Entrega'!$E$6:$E$9,"Víctor")+COUNTIFS('Entrega'!$B$6:$B$9,$A7,'Entrega'!$E$6:$E$9,"Ambos")+COUNTIFS('Defensa'!$B$6:$B$10,$A7,'Defensa'!$E$6:$E$10,"Víctor")+COUNTIFS('Defensa'!$B$6:$B$10,$A7,'Defensa'!$E$6:$E$10,"Ambos") | G7: =COUNTIFS('S1'!$B$6:$B$32,$A7,'S1'!$E$6:$E$32,"Diego")+COUNTIFS('S1'!$B$6:$B$32,$A7,'S1'!$E$6:$E$32,"Ambos")+COUNTIFS('S2'!$B$6:$B$23,$A7,'S2'!$E$6:$E$23,"Diego")+COUNTIFS('S2'!$B$6:$B$23,$A7,'S2'!$E$6:$E$23,"Ambos")+COUNTIFS('S3'!$B$6:$B$24,$A7,'S3'!$E$6:$E$24,"Diego")+COUNTIFS('S3'!$B$6:$B$24,$A7,'S3'!$E$6:$E$24,"Ambos")+COUNTIFS('S4'!$B$6:$B$22,$A7,'S4'!$E$6:$E$22,"Diego")+COUNTIFS('S4'!$B$6:$B$22,$A7,'S4'!$E$6:$E$22,"Ambos")+COUNTIFS('S5'!$B$6:$B$20,$A7,'S5'!$E$6:$E$20,"Diego")+COUNTIFS('S5'!$B$6:$B$20,$A7,'S5'!$E$6:$E$20,"Ambos")+COUNTIFS('S6'!$B$6:$B$17,$A7,'S6'!$E$6:$E$17,"Diego")+COUNTIFS('S6'!$B$6:$B$17,$A7,'S6'!$E$6:$E$17,"Ambos")+COUNTIFS('S7'!$B$6:$B$19,$A7,'S7'!$E$6:$E$19,"Diego")+COUNTIFS('S7'!$B$6:$B$19,$A7,'S7'!$E$6:$E$19,"Ambos")+COUNTIFS('S8'!$B$6:$B$23,$A7,'S8'!$E$6:$E$23,"Diego")+COUNTIFS('S8'!$B$6:$B$23,$A7,'S8'!$E$6:$E$23,"Ambos")+COUNTIFS('S9'!$B$6:$B$15,$A7,'S9'!$E$6:$E$15,"Diego")+COUNTIFS('S9'!$B$6:$B$15,$A7,'S9'!$E$6:$E$15,"Ambos")+COUNTIFS('S10'!$B$6:$B$13,$A7,'S10'!$E$6:$E$13,"Diego")+COUNTIFS('S10'!$B$6:$B$13,$A7,'S10'!$E$6:$E$13,"Ambos")+COUNTIFS('Holgura'!$B$6:$B$11,$A7,'Holgura'!$E$6:$E$11,"Diego")+COUNTIFS('Holgura'!$B$6:$B$11,$A7,'Holgura'!$E$6:$E$11,"Ambos")+COUNTIFS('Entrega'!$B$6:$B$9,$A7,'Entrega'!$E$6:$E$9,"Diego")+COUNTIFS('Entrega'!$B$6:$B$9,$A7,'Entrega'!$E$6:$E$9,"Ambos")+COUNTIFS('Defensa'!$B$6:$B$10,$A7,'Defensa'!$E$6:$E$10,"Diego")+COUNTIFS('Defensa'!$B$6:$B$10,$A7,'Defensa'!$E$6:$E$10,"Ambos")
A8: 46310 | B8: =A8 | C8: =IF(WEEKDAY(A8,2)>5,4,2) | D8: =SUMIFS('S1'!$I$6:$I$32,'S1'!$B$6:$B$32,$A8,'S1'!$E$6:$E$32,"Víctor")+SUMIFS('S1'!$I$6:$I$32,'S1'!$B$6:$B$32,$A8,'S1'!$E$6:$E$32,"Ambos")+SUMIFS('S2'!$I$6:$I$23,'S2'!$B$6:$B$23,$A8,'S2'!$E$6:$E$23,"Víctor")+SUMIFS('S2'!$I$6:$I$23,'S2'!$B$6:$B$23,$A8,'S2'!$E$6:$E$23,"Ambos")+SUMIFS('S3'!$I$6:$I$24,'S3'!$B$6:$B$24,$A8,'S3'!$E$6:$E$24,"Víctor")+SUMIFS('S3'!$I$6:$I$24,'S3'!$B$6:$B$24,$A8,'S3'!$E$6:$E$24,"Ambos")+SUMIFS('S4'!$I$6:$I$22,'S4'!$B$6:$B$22,$A8,'S4'!$E$6:$E$22,"Víctor")+SUMIFS('S4'!$I$6:$I$22,'S4'!$B$6:$B$22,$A8,'S4'!$E$6:$E$22,"Ambos")+SUMIFS('S5'!$I$6:$I$20,'S5'!$B$6:$B$20,$A8,'S5'!$E$6:$E$20,"Víctor")+SUMIFS('S5'!$I$6:$I$20,'S5'!$B$6:$B$20,$A8,'S5'!$E$6:$E$20,"Ambos")+SUMIFS('S6'!$I$6:$I$17,'S6'!$B$6:$B$17,$A8,'S6'!$E$6:$E$17,"Víctor")+SUMIFS('S6'!$I$6:$I$17,'S6'!$B$6:$B$17,$A8,'S6'!$E$6:$E$17,"Ambos")+SUMIFS('S7'!$I$6:$I$19,'S7'!$B$6:$B$19,$A8,'S7'!$E$6:$E$19,"Víctor")+SUMIFS('S7'!$I$6:$I$19,'S7'!$B$6:$B$19,$A8,'S7'!$E$6:$E$19,"Ambos")+SUMIFS('S8'!$I$6:$I$23,'S8'!$B$6:$B$23,$A8,'S8'!$E$6:$E$23,"Víctor")+SUMIFS('S8'!$I$6:$I$23,'S8'!$B$6:$B$23,$A8,'S8'!$E$6:$E$23,"Ambos")+SUMIFS('S9'!$I$6:$I$15,'S9'!$B$6:$B$15,$A8,'S9'!$E$6:$E$15,"Víctor")+SUMIFS('S9'!$I$6:$I$15,'S9'!$B$6:$B$15,$A8,'S9'!$E$6:$E$15,"Ambos")+SUMIFS('S10'!$I$6:$I$13,'S10'!$B$6:$B$13,$A8,'S10'!$E$6:$E$13,"Víctor")+SUMIFS('S10'!$I$6:$I$13,'S10'!$B$6:$B$13,$A8,'S10'!$E$6:$E$13,"Ambos")+SUMIFS('Holgura'!$I$6:$I$11,'Holgura'!$B$6:$B$11,$A8,'Holgura'!$E$6:$E$11,"Víctor")+SUMIFS('Holgura'!$I$6:$I$11,'Holgura'!$B$6:$B$11,$A8,'Holgura'!$E$6:$E$11,"Ambos")+SUMIFS('Entrega'!$I$6:$I$9,'Entrega'!$B$6:$B$9,$A8,'Entrega'!$E$6:$E$9,"Víctor")+SUMIFS('Entrega'!$I$6:$I$9,'Entrega'!$B$6:$B$9,$A8,'Entrega'!$E$6:$E$9,"Ambos")+SUMIFS('Defensa'!$I$6:$I$10,'Defensa'!$B$6:$B$10,$A8,'Defensa'!$E$6:$E$10,"Víctor")+SUMIFS('Defensa'!$I$6:$I$10,'Defensa'!$B$6:$B$10,$A8,'Defensa'!$E$6:$E$10,"Ambos") | E8: =SUMIFS('S1'!$I$6:$I$32,'S1'!$B$6:$B$32,$A8,'S1'!$E$6:$E$32,"Diego")+SUMIFS('S1'!$I$6:$I$32,'S1'!$B$6:$B$32,$A8,'S1'!$E$6:$E$32,"Ambos")+SUMIFS('S2'!$I$6:$I$23,'S2'!$B$6:$B$23,$A8,'S2'!$E$6:$E$23,"Diego")+SUMIFS('S2'!$I$6:$I$23,'S2'!$B$6:$B$23,$A8,'S2'!$E$6:$E$23,"Ambos")+SUMIFS('S3'!$I$6:$I$24,'S3'!$B$6:$B$24,$A8,'S3'!$E$6:$E$24,"Diego")+SUMIFS('S3'!$I$6:$I$24,'S3'!$B$6:$B$24,$A8,'S3'!$E$6:$E$24,"Ambos")+SUMIFS('S4'!$I$6:$I$22,'S4'!$B$6:$B$22,$A8,'S4'!$E$6:$E$22,"Diego")+SUMIFS('S4'!$I$6:$I$22,'S4'!$B$6:$B$22,$A8,'S4'!$E$6:$E$22,"Ambos")+SUMIFS('S5'!$I$6:$I$20,'S5'!$B$6:$B$20,$A8,'S5'!$E$6:$E$20,"Diego")+SUMIFS('S5'!$I$6:$I$20,'S5'!$B$6:$B$20,$A8,'S5'!$E$6:$E$20,"Ambos")+SUMIFS('S6'!$I$6:$I$17,'S6'!$B$6:$B$17,$A8,'S6'!$E$6:$E$17,"Diego")+SUMIFS('S6'!$I$6:$I$17,'S6'!$B$6:$B$17,$A8,'S6'!$E$6:$E$17,"Ambos")+SUMIFS('S7'!$I$6:$I$19,'S7'!$B$6:$B$19,$A8,'S7'!$E$6:$E$19,"Diego")+SUMIFS('S7'!$I$6:$I$19,'S7'!$B$6:$B$19,$A8,'S7'!$E$6:$E$19,"Ambos")+SUMIFS('S8'!$I$6:$I$23,'S8'!$B$6:$B$23,$A8,'S8'!$E$6:$E$23,"Diego")+SUMIFS('S8'!$I$6:$I$23,'S8'!$B$6:$B$23,$A8,'S8'!$E$6:$E$23,"Ambos")+SUMIFS('S9'!$I$6:$I$15,'S9'!$B$6:$B$15,$A8,'S9'!$E$6:$E$15,"Diego")+SUMIFS('S9'!$I$6:$I$15,'S9'!$B$6:$B$15,$A8,'S9'!$E$6:$E$15,"Ambos")+SUMIFS('S10'!$I$6:$I$13,'S10'!$B$6:$B$13,$A8,'S10'!$E$6:$E$13,"Diego")+SUMIFS('S10'!$I$6:$I$13,'S10'!$B$6:$B$13,$A8,'S10'!$E$6:$E$13,"Ambos")+SUMIFS('Holgura'!$I$6:$I$11,'Holgura'!$B$6:$B$11,$A8,'Holgura'!$E$6:$E$11,"Diego")+SUMIFS('Holgura'!$I$6:$I$11,'Holgura'!$B$6:$B$11,$A8,'Holgura'!$E$6:$E$11,"Ambos")+SUMIFS('Entrega'!$I$6:$I$9,'Entrega'!$B$6:$B$9,$A8,'Entrega'!$E$6:$E$9,"Diego")+SUMIFS('Entrega'!$I$6:$I$9,'Entrega'!$B$6:$B$9,$A8,'Entrega'!$E$6:$E$9,"Ambos")+SUMIFS('Defensa'!$I$6:$I$10,'Defensa'!$B$6:$B$10,$A8,'Defensa'!$E$6:$E$10,"Diego")+SUMIFS('Defensa'!$I$6:$I$10,'Defensa'!$B$6:$B$10,$A8,'Defensa'!$E$6:$E$10,"Ambos") | F8: =COUNTIFS('S1'!$B$6:$B$32,$A8,'S1'!$E$6:$E$32,"Víctor")+COUNTIFS('S1'!$B$6:$B$32,$A8,'S1'!$E$6:$E$32,"Ambos")+COUNTIFS('S2'!$B$6:$B$23,$A8,'S2'!$E$6:$E$23,"Víctor")+COUNTIFS('S2'!$B$6:$B$23,$A8,'S2'!$E$6:$E$23,"Ambos")+COUNTIFS('S3'!$B$6:$B$24,$A8,'S3'!$E$6:$E$24,"Víctor")+COUNTIFS('S3'!$B$6:$B$24,$A8,'S3'!$E$6:$E$24,"Ambos")+COUNTIFS('S4'!$B$6:$B$22,$A8,'S4'!$E$6:$E$22,"Víctor")+COUNTIFS('S4'!$B$6:$B$22,$A8,'S4'!$E$6:$E$22,"Ambos")+COUNTIFS('S5'!$B$6:$B$20,$A8,'S5'!$E$6:$E$20,"Víctor")+COUNTIFS('S5'!$B$6:$B$20,$A8,'S5'!$E$6:$E$20,"Ambos")+COUNTIFS('S6'!$B$6:$B$17,$A8,'S6'!$E$6:$E$17,"Víctor")+COUNTIFS('S6'!$B$6:$B$17,$A8,'S6'!$E$6:$E$17,"Ambos")+COUNTIFS('S7'!$B$6:$B$19,$A8,'S7'!$E$6:$E$19,"Víctor")+COUNTIFS('S7'!$B$6:$B$19,$A8,'S7'!$E$6:$E$19,"Ambos")+COUNTIFS('S8'!$B$6:$B$23,$A8,'S8'!$E$6:$E$23,"Víctor")+COUNTIFS('S8'!$B$6:$B$23,$A8,'S8'!$E$6:$E$23,"Ambos")+COUNTIFS('S9'!$B$6:$B$15,$A8,'S9'!$E$6:$E$15,"Víctor")+COUNTIFS('S9'!$B$6:$B$15,$A8,'S9'!$E$6:$E$15,"Ambos")+COUNTIFS('S10'!$B$6:$B$13,$A8,'S10'!$E$6:$E$13,"Víctor")+COUNTIFS('S10'!$B$6:$B$13,$A8,'S10'!$E$6:$E$13,"Ambos")+COUNTIFS('Holgura'!$B$6:$B$11,$A8,'Holgura'!$E$6:$E$11,"Víctor")+COUNTIFS('Holgura'!$B$6:$B$11,$A8,'Holgura'!$E$6:$E$11,"Ambos")+COUNTIFS('Entrega'!$B$6:$B$9,$A8,'Entrega'!$E$6:$E$9,"Víctor")+COUNTIFS('Entrega'!$B$6:$B$9,$A8,'Entrega'!$E$6:$E$9,"Ambos")+COUNTIFS('Defensa'!$B$6:$B$10,$A8,'Defensa'!$E$6:$E$10,"Víctor")+COUNTIFS('Defensa'!$B$6:$B$10,$A8,'Defensa'!$E$6:$E$10,"Ambos") | G8: =COUNTIFS('S1'!$B$6:$B$32,$A8,'S1'!$E$6:$E$32,"Diego")+COUNTIFS('S1'!$B$6:$B$32,$A8,'S1'!$E$6:$E$32,"Ambos")+COUNTIFS('S2'!$B$6:$B$23,$A8,'S2'!$E$6:$E$23,"Diego")+COUNTIFS('S2'!$B$6:$B$23,$A8,'S2'!$E$6:$E$23,"Ambos")+COUNTIFS('S3'!$B$6:$B$24,$A8,'S3'!$E$6:$E$24,"Diego")+COUNTIFS('S3'!$B$6:$B$24,$A8,'S3'!$E$6:$E$24,"Ambos")+COUNTIFS('S4'!$B$6:$B$22,$A8,'S4'!$E$6:$E$22,"Diego")+COUNTIFS('S4'!$B$6:$B$22,$A8,'S4'!$E$6:$E$22,"Ambos")+COUNTIFS('S5'!$B$6:$B$20,$A8,'S5'!$E$6:$E$20,"Diego")+COUNTIFS('S5'!$B$6:$B$20,$A8,'S5'!$E$6:$E$20,"Ambos")+COUNTIFS('S6'!$B$6:$B$17,$A8,'S6'!$E$6:$E$17,"Diego")+COUNTIFS('S6'!$B$6:$B$17,$A8,'S6'!$E$6:$E$17,"Ambos")+COUNTIFS('S7'!$B$6:$B$19,$A8,'S7'!$E$6:$E$19,"Diego")+COUNTIFS('S7'!$B$6:$B$19,$A8,'S7'!$E$6:$E$19,"Ambos")+COUNTIFS('S8'!$B$6:$B$23,$A8,'S8'!$E$6:$E$23,"Diego")+COUNTIFS('S8'!$B$6:$B$23,$A8,'S8'!$E$6:$E$23,"Ambos")+COUNTIFS('S9'!$B$6:$B$15,$A8,'S9'!$E$6:$E$15,"Diego")+COUNTIFS('S9'!$B$6:$B$15,$A8,'S9'!$E$6:$E$15,"Ambos")+COUNTIFS('S10'!$B$6:$B$13,$A8,'S10'!$E$6:$E$13,"Diego")+COUNTIFS('S10'!$B$6:$B$13,$A8,'S10'!$E$6:$E$13,"Ambos")+COUNTIFS('Holgura'!$B$6:$B$11,$A8,'Holgura'!$E$6:$E$11,"Diego")+COUNTIFS('Holgura'!$B$6:$B$11,$A8,'Holgura'!$E$6:$E$11,"Ambos")+COUNTIFS('Entrega'!$B$6:$B$9,$A8,'Entrega'!$E$6:$E$9,"Diego")+COUNTIFS('Entrega'!$B$6:$B$9,$A8,'Entrega'!$E$6:$E$9,"Ambos")+COUNTIFS('Defensa'!$B$6:$B$10,$A8,'Defensa'!$E$6:$E$10,"Diego")+COUNTIFS('Defensa'!$B$6:$B$10,$A8,'Defensa'!$E$6:$E$10,"Ambos")
